Internal Server Error: /admin/auth/user/
Traceback (most recent call last):
  File "C:\Users\sanju\AppData\Local\Programs\Python\Python310\lib\site-packages\django\db\backends\base\base.py", line 303, in _commit
    return self.connection.commit()
psycopg2.errors.ForeignKeyViolation: update or delete on table "auth_user" violates foreign key constraint "reports_issue_reported_users_user_id_903ef09c_fk_auth_user_id" on table "reports_issue_reported_users"
DETAIL:  Key (id)=(7) is still referenced from table "reports_issue_reported_users".


The above exception was the direct cause of the following exception:

Traceback (most recent call last):
  File "C:\Users\sanju\AppData\Local\Programs\Python\Python310\lib\site-packages\django\core\handlers\exception.py", line 55, in inner
    response = get_response(request)
  File "C:\Users\sanju\AppData\Local\Programs\Python\Python310\lib\site-packages\django\core\handlers\base.py", line 197, in _get_response
    response = wrapped_callback(request, *callback_args, **callback_kwargs)
  File "C:\Users\sanju\AppData\Local\Programs\Python\Python310\lib\site-packages\django\contrib\admin\options.py", line 719, in wrapper
    return self.admin_site.admin_view(view)(*args, **kwargs)
  File "C:\Users\sanju\AppData\Local\Programs\Python\Python310\lib\site-packages\django\utils\decorators.py", line 192, in _view_wrapper
    result = _process_exception(request, e)
  File "C:\Users\sanju\AppData\Local\Programs\Python\Python310\lib\site-packages\django\utils\decorators.py", line 190, in _view_wrapper
    response = view_func(request, *args, **kwargs)
  File "C:\Users\sanju\AppData\Local\Programs\Python\Python310\lib\site-packages\django\views\decorators\cache.py", line 80, in _view_wrapper
    response = view_func(request, *args, **kwargs)
  File "C:\Users\sanju\AppData\Local\Programs\Python\Python310\lib\site-packages\django\contrib\admin\sites.py", line 246, in inner
    return view(request, *args, **kwargs)
  File "C:\Users\sanju\AppData\Local\Programs\Python\Python310\lib\site-packages\django\utils\decorators.py", line 48, in _wrapper
    return bound_method(*args, **kwargs)
  File "C:\Users\sanju\AppData\Local\Programs\Python\Python310\lib\site-packages\django\utils\decorators.py", line 192, in _view_wrapper
    result = _process_exception(request, e)
  File "C:\Users\sanju\AppData\Local\Programs\Python\Python310\lib\site-packages\django\utils\decorators.py", line 190, in _view_wrapper
    response = view_func(request, *args, **kwargs)
  File "C:\Users\sanju\AppData\Local\Programs\Python\Python310\lib\site-packages\django\contrib\admin\options.py", line 2081, in changelist_view
    response = self.response_action(
  File "C:\Users\sanju\AppData\Local\Programs\Python\Python310\lib\site-packages\django\contrib\admin\options.py", line 1686, in response_action
    response = func(self, request, queryset)
  File "C:\Users\sanju\AppData\Local\Programs\Python\Python310\lib\site-packages\django\contrib\admin\actions.py", line 49, in delete_selected
    modeladmin.delete_queryset(request, queryset)
  File "C:\Users\sanju\AppData\Local\Programs\Python\Python310\lib\site-packages\django\contrib\admin\options.py", line 1324, in delete_queryset
    queryset.delete()
  File "C:\Users\sanju\AppData\Local\Programs\Python\Python310\lib\site-packages\django\db\models\query.py", line 1197, in delete
    num_deleted, num_deleted_per_model = collector.delete()
  File "C:\Users\sanju\AppData\Local\Programs\Python\Python310\lib\site-packages\django\db\models\deletion.py", line 454, in delete
    with transaction.atomic(using=self.using, savepoint=False):
  File "C:\Users\sanju\AppData\Local\Programs\Python\Python310\lib\site-packages\django\db\transaction.py", line 263, in __exit__
    connection.commit()
  File "C:\Users\sanju\AppData\Local\Programs\Python\Python310\lib\site-packages\django\utils\asyncio.py", line 26, in inner
    return func(*args, **kwargs)
  File "C:\Users\sanju\AppData\Local\Programs\Python\Python310\lib\site-packages\django\db\backends\base\base.py", line 327, in commit
    self._commit()
  File "C:\Users\sanju\AppData\Local\Programs\Python\Python310\lib\site-packages\django\db\backends\base\base.py", line 302, in _commit
    with debug_transaction(self, "COMMIT"), self.wrap_database_errors:
  File "C:\Users\sanju\AppData\Local\Programs\Python\Python310\lib\site-packages\django\db\utils.py", line 91, in __exit__
    raise dj_exc_value.with_traceback(traceback) from exc_value
  File "C:\Users\sanju\AppData\Local\Programs\Python\Python310\lib\site-packages\django\db\backends\base\base.py", line 303, in _commit
    return self.connection.commit()
django.db.utils.IntegrityError: update or delete on table "auth_user" violates foreign key constraint "reports_issue_reported_users_user_id_903ef09c_fk_auth_user_id" on table "reports_issue_reported_users"
DETAIL:  Key (id)=(7) is still referenced from table "reports_issue_reported_users".

"POST /admin/auth/user/ HTTP/1.1" 500 165165
Internal Server Error: /report_issue/
Traceback (most recent call last):
  File "C:\Users\sanju\AppData\Local\Programs\Python\Python310\lib\site-packages\django\core\handlers\exception.py", line 55, in inner
    response = get_response(request)
  File "C:\Users\sanju\AppData\Local\Programs\Python\Python310\lib\site-packages\django\core\handlers\base.py", line 197, in _get_response
    response = wrapped_callback(request, *callback_args, **callback_kwargs)
  File "C:\Users\sanju\AppData\Local\Programs\Python\Python310\lib\site-packages\django\contrib\auth\decorators.py", line 59, in _view_wrapper
    return view_func(request, *args, **kwargs)
  File "C:\Users\sanju\Desktop\tbppro\tbp\civicconnect\reports\views.py", line 78, in report_issue
    latitude = float(request.POST.get("latitude"))
ValueError: could not convert string to float: 'null'
"POST /report_issue/ HTTP/1.1" 500 73067
Internal Server Error: /report_issue/
Traceback (most recent call last):
  File "C:\Users\sanju\AppData\Local\Programs\Python\Python310\lib\site-packages\django\db\backends\utils.py", line 105, in _execute
    return self.cursor.execute(sql, params)
psycopg2.errors.UniqueViolation: duplicate key value violates unique constraint "unique_issue_location"
DETAIL:  Key (description, latitude, longitude)=(there is a open manhole near the bus stop, 17.310587530310226, 78.42357656206363) already exists.


The above exception was the direct cause of the following exception:

Traceback (most recent call last):
  File "C:\Users\sanju\AppData\Local\Programs\Python\Python310\lib\site-packages\django\core\handlers\exception.py", line 55, in inner
    response = get_response(request)
  File "C:\Users\sanju\AppData\Local\Programs\Python\Python310\lib\site-packages\django\core\handlers\base.py", line 197, in _get_response
    response = wrapped_callback(request, *callback_args, **callback_kwargs)
  File "C:\Users\sanju\AppData\Local\Programs\Python\Python310\lib\site-packages\django\contrib\auth\decorators.py", line 59, in _view_wrapper
    return view_func(request, *args, **kwargs)
  File "C:\Users\sanju\Desktop\tbppro\tbp\civicconnect\reports\views.py", line 105, in report_issue
    new_issue = Issue.objects.create(
  File "C:\Users\sanju\AppData\Local\Programs\Python\Python310\lib\site-packages\django\db\models\manager.py", line 87, in manager_method
    return getattr(self.get_queryset(), name)(*args, **kwargs)
  File "C:\Users\sanju\AppData\Local\Programs\Python\Python310\lib\site-packages\django\db\models\query.py", line 663, in create
    obj.save(force_insert=True, using=self.db)
  File "C:\Users\sanju\Desktop\tbppro\tbp\civicconnect\reports\models.py", line 70, in save
    super().save(*args, **kwargs)
  File "C:\Users\sanju\AppData\Local\Programs\Python\Python310\lib\site-packages\django\db\models\base.py", line 902, in save
    self.save_base(
  File "C:\Users\sanju\AppData\Local\Programs\Python\Python310\lib\site-packages\django\db\models\base.py", line 1008, in save_base
    updated = self._save_table(
  File "C:\Users\sanju\AppData\Local\Programs\Python\Python310\lib\site-packages\django\db\models\base.py", line 1169, in _save_table
    results = self._do_insert(
  File "C:\Users\sanju\AppData\Local\Programs\Python\Python310\lib\site-packages\django\db\models\base.py", line 1210, in _do_insert
    return manager._insert(
  File "C:\Users\sanju\AppData\Local\Programs\Python\Python310\lib\site-packages\django\db\models\manager.py", line 87, in manager_method
    return getattr(self.get_queryset(), name)(*args, **kwargs)
  File "C:\Users\sanju\AppData\Local\Programs\Python\Python310\lib\site-packages\django\db\models\query.py", line 1854, in _insert
    return query.get_compiler(using=using).execute_sql(returning_fields)
  File "C:\Users\sanju\AppData\Local\Programs\Python\Python310\lib\site-packages\django\db\models\sql\compiler.py", line 1881, in execute_sql
    cursor.execute(sql, params)
  File "C:\Users\sanju\AppData\Local\Programs\Python\Python310\lib\site-packages\django\db\backends\utils.py", line 122, in execute
    return super().execute(sql, params)
  File "C:\Users\sanju\AppData\Local\Programs\Python\Python310\lib\site-packages\django\db\backends\utils.py", line 79, in execute
    return self._execute_with_wrappers(
  File "C:\Users\sanju\AppData\Local\Programs\Python\Python310\lib\site-packages\django\db\backends\utils.py", line 92, in _execute_with_wrappers
    return executor(sql, params, many, context)
  File "C:\Users\sanju\AppData\Local\Programs\Python\Python310\lib\site-packages\django\db\backends\utils.py", line 100, in _execute
    with self.db.wrap_database_errors:
  File "C:\Users\sanju\AppData\Local\Programs\Python\Python310\lib\site-packages\django\db\utils.py", line 91, in __exit__
    raise dj_exc_value.with_traceback(traceback) from exc_value
  File "C:\Users\sanju\AppData\Local\Programs\Python\Python310\lib\site-packages\django\db\backends\utils.py", line 105, in _execute
    return self.cursor.execute(sql, params)
django.db.utils.IntegrityError: duplicate key value violates unique constraint "unique_issue_location"
DETAIL:  Key (description, latitude, longitude)=(there is a open manhole near the bus stop, 17.310587530310226, 78.42357656206363) already exists.

"POST /report_issue/ HTTP/1.1" 500 182142
Internal Server Error: /report_issue/
Traceback (most recent call last):
  File "C:\Users\sanju\AppData\Local\Programs\Python\Python310\lib\site-packages\django\core\handlers\exception.py", line 55, in inner
    response = get_response(request)
  File "C:\Users\sanju\AppData\Local\Programs\Python\Python310\lib\site-packages\django\core\handlers\base.py", line 197, in _get_response
    response = wrapped_callback(request, *callback_args, **callback_kwargs)
  File "C:\Users\sanju\AppData\Local\Programs\Python\Python310\lib\site-packages\django\contrib\auth\decorators.py", line 59, in _view_wrapper
    return view_func(request, *args, **kwargs)
  File "C:\Users\sanju\Desktop\tbppro\tbp\civicconnect\reports\views.py", line 79, in report_issue
    latitude = float(request.POST.get("latitude"))
ValueError: could not convert string to float: 'null'
"POST /report_issue/ HTTP/1.1" 500 75174
Internal Server Error: /report_issue/
Traceback (most recent call last):
  File "C:\Users\sanju\AppData\Local\Programs\Python\Python310\lib\site-packages\django\core\handlers\exception.py", line 55, in inner
    response = get_response(request)
  File "C:\Users\sanju\AppData\Local\Programs\Python\Python310\lib\site-packages\django\core\handlers\base.py", line 197, in _get_response
    response = wrapped_callback(request, *callback_args, **callback_kwargs)
  File "C:\Users\sanju\AppData\Local\Programs\Python\Python310\lib\site-packages\django\contrib\auth\decorators.py", line 59, in _view_wrapper
    return view_func(request, *args, **kwargs)
  File "C:\Users\sanju\Desktop\tbppro\tbp\civicconnect\reports\views.py", line 79, in report_issue
    latitude = float(request.POST.get("latitude"))
ValueError: could not convert string to float: 'null'
"POST /report_issue/ HTTP/1.1" 500 75174
Internal Server Error: /report_issue/
Traceback (most recent call last):
  File "C:\Users\sanju\AppData\Local\Programs\Python\Python310\lib\site-packages\django\core\handlers\exception.py", line 55, in inner
    response = get_response(request)
  File "C:\Users\sanju\AppData\Local\Programs\Python\Python310\lib\site-packages\django\core\handlers\base.py", line 197, in _get_response
    response = wrapped_callback(request, *callback_args, **callback_kwargs)
  File "C:\Users\sanju\AppData\Local\Programs\Python\Python310\lib\site-packages\django\contrib\auth\decorators.py", line 59, in _view_wrapper
    return view_func(request, *args, **kwargs)
  File "C:\Users\sanju\Desktop\tbppro\tbp\civicconnect\reports\views.py", line 79, in report_issue
    latitude = float(request.POST.get("latitude"))
ValueError: could not convert string to float: 'null'
"POST /report_issue/ HTTP/1.1" 500 74769
Internal Server Error: /report_issue/
Traceback (most recent call last):
  File "C:\Users\sanju\AppData\Local\Programs\Python\Python310\lib\site-packages\django\core\handlers\exception.py", line 55, in inner
    response = get_response(request)
  File "C:\Users\sanju\AppData\Local\Programs\Python\Python310\lib\site-packages\django\core\handlers\base.py", line 197, in _get_response
    response = wrapped_callback(request, *callback_args, **callback_kwargs)
  File "C:\Users\sanju\AppData\Local\Programs\Python\Python310\lib\site-packages\django\contrib\auth\decorators.py", line 59, in _view_wrapper
    return view_func(request, *args, **kwargs)
  File "C:\Users\sanju\Desktop\tbppro\tbp\civicconnect\reports\views.py", line 79, in report_issue
    latitude = float(request.POST.get("latitude"))
ValueError: could not convert string to float: 'null'
"POST /report_issue/ HTTP/1.1" 500 75189
